Workbook

Sheet storm_data_search_results
A1: EVENT_ID | B1: CZ_NAME_STR | C1: GEONAME | D1: GeoFips | E1: BEGIN_LOCATION | F1: BEGIN_DATE | G1: BEGIN_TIME | H1: EVENT_TYPE | I1: MAGNITUDE | J1: TOR_F_SCALE | K1: DEATHS_DIRECT | L1: INJURIES_DIRECT | M1: DAMAGE_PROPERTY_NUM | N1: DAMAGE_CROPS_NUM | O1: STATE_ABBR | P1: CZ_TIMEZONE | Q1: MAGNITUDE_TYPE | R1: EPISODE_ID | S1: CZ_TYPE | T1: CZ_FIPS | U1: WFO | V1: INJURIES_INDIRECT | W1: DEATHS_INDIRECT | X1: SOURCE | Y1: FLOOD_CAUSE | Z1: TOR_LENGTH | AA1: TOR_WIDTH | AB1: BEGIN_RANGE | AC1: BEGIN_AZIMUTH | AD1: END_RANGE | AE1: END_AZIMUTH | AF1: END_LOCATION | AG1: END_DATE | AH1: END_TIME | AI1: BEGIN_LAT | AJ1: BEGIN_LON | AK1: END_LAT | AL1: END_LON | AM1: EVENT_NARRATIVE | AN1: EPISODE_NARRATIVE | AO1: ABSOLUTE_ROWNUMBER
A2: 5716192 | B2: COASTAL PALM BEACH (ZONE) | C2: =_xlfn.XLOOKUP(B2,Match!$A$2:$A$111,Match!$B$2:$B$111) -> Palm Beach, FL | D2: =_xlfn.XLOOKUP(C2,Validation!$B$2:$B$68,Validation!$A$2:$A$68) -> 12099 | F2: 36401 | G2: 2330 | H2: Hurricane (Typhoon) | K2: 1 | L2: 0 | M2: 100000 | N2: 0 | O2: FL | P2: EST | R2: 2412133 | S2: Z | T2: 68 | U2: MFL | V2: 0 | W2: 0 | X2: NEWSPAPER | AG2: 36401 | AH2: 2330 | AN2: Large swells from Hurricane Dennis, which at the time was located off the North Carolina coast, swamped six small boats, mainly at Boca Raton and Hillsboro Inlets. One person was washed overboard and drowned. The swells also caused mostly minor beach erosion along the Palm Beach and Broward county shorelines. | AO2: 85
A3: 5716202 | B3: COASTAL DADE (ZONE) | C3: =_xlfn.XLOOKUP(B3,Match!$A$2:$A$111,Match!$B$2:$B$111) -> Miami-Dade, FL | D3: =_xlfn.XLOOKUP(C3,Validation!$B$2:$B$68,Validation!$A$2:$A$68) -> 12086 | F3: 36416 | G3: 1200 | H3: Hurricane (Typhoon) | K3: 0 | L3: 0 | M3: 0 | N3: 0 | O3: FL | P3: EST | R3: 2412137 | S3: Z | T3: 74 | U3: MFL | V3: 0 | W3: 0 | X3: NEWSPAPER | AG3: 36417 | AH3: 2300 | AN3: Large and powerful hurricane Floyd, approached the southeast Florida coast on September 13 and moved north of the area by September 15. Southeast Florida remained on the weak" side of Floyd with minimal effects | AO3: mostly to marine interests. Total damage from Floyd in south Florida is estimated at $100 thousand | AP3: most of which was in Palm Beach county. This figure does not include preparation costs which were estimated to have been near $3 million in Palm Beach County alone.
A4: 5716201 | B4: COASTAL BROWARD (ZONE) | C4: =_xlfn.XLOOKUP(B4,Match!$A$2:$A$111,Match!$B$2:$B$111) -> Broward, FL | D4: =_xlfn.XLOOKUP(C4,Validation!$B$2:$B$68,Validation!$A$2:$A$68) -> 12011 | F4: 36416 | G4: 1200 | H4: Hurricane (Typhoon) | K4: 0 | L4: 0 | M4: 0 | N4: 0 | O4: FL | P4: EST | R4: 2412137 | S4: Z | T4: 72 | U4: MFL | V4: 0 | W4: 0 | X4: NEWSPAPER | AG4: 36417 | AH4: 2300 | AN4: Large and powerful hurricane Floyd, approached the southeast Florida coast on September 13 and moved north of the area by September 15. Southeast Florida remained on the weak" side of Floyd with minimal effects | AO4: mostly to marine interests. Total damage from Floyd in south Florida is estimated at $100 thousand | AP4: most of which was in Palm Beach county. This figure does not include preparation costs which were estimated to have been near $3 million in Palm Beach County alone.
A5: 5716203 | B5: COASTAL PALM BEACH (ZONE) | C5: =_xlfn.XLOOKUP(B5,Match!$A$2:$A$111,Match!$B$2:$B$111) -> Palm Beach, FL | D5: =_xlfn.XLOOKUP(C5,Validation!$B$2:$B$68,Validation!$A$2:$A$68) -> 12099 | F5: 36416 | G5: 1200 | H5: Hurricane (Typhoon) | K5: 0 | L5: 0 | M5: 100000 | N5: 0 | O5: FL | P5: EST | R5: 2412137 | S5: Z | T5: 68 | U5: MFL | V5: 0 | W5: 0 | X5: NEWSPAPER | AG5: 36417 | AH5: 2300 | AN5: Large and powerful hurricane Floyd, approached the southeast Florida coast on September 13 and moved north of the area by September 15. Southeast Florida remained on the weak" side of Floyd with minimal effects | AO5: mostly to marine interests. Total damage from Floyd in south Florida is estimated at $100 thousand | AP5: most of which was in Palm Beach county. This figure does not include preparation costs which were estimated to have been near $3 million in Palm Beach County alone.
A6: 5717086 | B6: DE SOTO (ZONE) | C6: =_xlfn.XLOOKUP(B6,Match!$A$2:$A$111,Match!$B$2:$B$111) -> DeSoto, FL | D6: =_xlfn.XLOOKUP(C6,Validation!$B$2:$B$68,Validation!$A$2:$A$68) -> 12027 | F6: 36417 | G6: 1200 | H6: Hurricane (Typhoon) | K6: 0 | L6: 0 | M6: 0 | N6: 0 | O6: FL | P6: EST | R6: 2412730 | S6: Z | T6: 61 | U6: TBW | V6: 0 | W6: 0 | X6: OFFICIAL NWS OBS. | AG6: 36417 | AH6: 1800 | AN6: The outer rainbands of hurricane Floyd moved parallel to the east coast of Florida and produced tropical storm force wind gusts primarily across interior counties within West Central Florida. A maximum wind gust of 58 mph was reported at Lakeland Linder Airport around 1700 EST on the 14th._x000D_ _x000D_ Tropical storm force wind gusts uprooted a few large trees and downed power lines in and around Lakeland in Polk County. One mobile home lost its roof from tropical storm force winds on Rock Ridge Road in Lakeland. | AO6: 89
A7: 5717083 | B7: LEE (ZONE) | C7: =_xlfn.XLOOKUP(B7,Match!$A$2:$A$111,Match!$B$2:$B$111) -> Lee, FL | D7: =_xlfn.XLOOKUP(C7,Validation!$B$2:$B$68,Validation!$A$2:$A$68) -> 12071 | F7: 36417 | G7: 1200 | H7: Hurricane (Typhoon) | K7: 0 | L7: 0 | M7: 0 | N7: 0 | O7: FL | P7: EST | R7: 2412730 | S7: Z | T7: 65 | U7: TBW | V7: 0 | W7: 0 | X7: OFFICIAL NWS OBS. | AG7: 36417 | AH7: 1800 | AN7: The outer rainbands of hurricane Floyd moved parallel to the east coast of Florida and produced tropical storm force wind gusts primarily across interior counties within West Central Florida. A maximum wind gust of 58 mph was reported at Lakeland Linder Airport around 1700 EST on the 14th._x000D_ _x000D_ Tropical storm force wind gusts uprooted a few large trees and downed power lines in and around Lakeland in Polk County. One mobile home lost its roof from tropical storm force winds on Rock Ridge Road in Lakeland. | AO7: 90
A8: 5717081 | B8: HIGHLANDS (ZONE) | C8: =_xlfn.XLOOKUP(B8,Match!$A$2:$A$111,Match!$B$2:$B$111) -> Highlands, FL | D8: =_xlfn.XLOOKUP(C8,Validation!$B$2:$B$68,Validation!$A$2:$A$68) -> 12055 | F8: 36417 | G8: 1200 | H8: Hurricane (Typhoon) | K8: 0 | L8: 0 | M8: 0 | N8: 0 | O8: FL | P8: EST | R8: 2412730 | S8: Z | T8: 57 | U8: TBW | V8: 0 | W8: 0 | X8: OFFICIAL NWS OBS. | AG8: 36417 | AH8: 1800 | AN8: The outer rainbands of hurricane Floyd moved parallel to the east coast of Florida and produced tropical storm force wind gusts primarily across interior counties within West Central Florida. A maximum wind gust of 58 mph was reported at Lakeland Linder Airport around 1700 EST on the 14th._x000D_ _x000D_ Tropical storm force wind gusts uprooted a few large trees and downed power lines in and around Lakeland in Polk County. One mobile home lost its roof from tropical storm force winds on Rock Ridge Road in Lakeland. | AO8: 91
A9: 5717080 | B9: CHARLOTTE (ZONE) | C9: =_xlfn.XLOOKUP(B9,Match!$A$2:$A$111,Match!$B$2:$B$111) -> Charlotte, FL | D9: =_xlfn.XLOOKUP(C9,Validation!$B$2:$B$68,Validation!$A$2:$A$68) -> 12015 | F9: 36417 | G9: 1200 | H9: Hurricane (Typhoon) | K9: 0 | L9: 0 | M9: 0 | N9: 0 | O9: FL | P9: EST | R9: 2412730 | S9: Z | T9: 62 | U9: TBW | V9: 0 | W9: 0 | X9: OFFICIAL NWS OBS. | AG9: 36417 | AH9: 1800 | AN9: The outer rainbands of hurricane Floyd moved parallel to the east coast of Florida and produced tropical storm force wind gusts primarily across interior counties within West Central Florida. A maximum wind gust of 58 mph was reported at Lakeland Linder Airport around 1700 EST on the 14th._x000D_ _x000D_ Tropical storm force wind gusts uprooted a few large trees and downed power lines in and around Lakeland in Polk County. One mobile home lost its roof from tropical storm force winds on Rock Ridge Road in Lakeland. | AO9: 92
A10: 5717079 | B10: POLK (ZONE) | C10: =_xlfn.XLOOKUP(B10,Match!$A$2:$A$111,Match!$B$2:$B$111) -> Polk, FL | D10: =_xlfn.XLOOKUP(C10,Validation!$B$2:$B$68,Validation!$A$2:$A$68) -> 12105 | F10: 36417 | G10: 1200 | H10: Hurricane (Typhoon) | K10: 0 | L10: 0 | M10: 20000 | N10: 0 | O10: FL | P10: EST | R10: 2412730 | S10: Z | T10: 52 | U10: TBW | V10: 0 | W10: 0 | X10: OFFICIAL NWS OBS. | AG10: 36417 | AH10: 1800 | AN10: The outer rainbands of hurricane Floyd moved parallel to the east coast of Florida and produced tropical storm force wind gusts primarily across interior counties within West Central Florida. A maximum wind gust of 58 mph was reported at Lakeland Linder Airport around 1700 EST on the 14th._x000D_ _x000D_ Tropical storm force wind gusts uprooted a few large trees and downed power lines in and around Lakeland in Polk County. One mobile home lost its roof from tropical storm force winds on Rock Ridge Road in Lakeland. | AO10: 93
A11: 5717082 | B11: HILLSBOROUGH (ZONE) | C11: =_xlfn.XLOOKUP(B11,Match!$A$2:$A$111,Match!$B$2:$B$111) -> Hillsborough, FL | D11: =_xlfn.XLOOKUP(C11,Validation!$B$2:$B$68,Validation!$A$2:$A$68) -> 12057 | F11: 36417 | G11: 1200 | H11: Hurricane (Typhoon) | K11: 0 | L11: 0 | M11: 0 | N11: 0 | O11: FL | P11: EST | R11: 2412730 | S11: Z | T11: 51 | U11: TBW | V11: 0 | W11: 0 | X11: OFFICIAL NWS OBS. | AG11: 36417 | AH11: 1800 | AN11: The outer rainbands of hurricane Floyd moved parallel to the east coast of Florida and produced tropical storm force wind gusts primarily across interior counties within West Central Florida. A maximum wind gust of 58 mph was reported at Lakeland Linder Airport around 1700 EST on the 14th._x000D_ _x000D_ Tropical storm force wind gusts uprooted a few large trees and downed power lines in and around Lakeland in Polk County. One mobile home lost its roof from tropical storm force winds on Rock Ridge Road in Lakeland. | AO11: 94
A12: 5717085 | B12: SARASOTA (ZONE) | C12: =_xlfn.XLOOKUP(B12,Match!$A$2:$A$111,Match!$B$2:$B$111) -> Sarasota, FL | D12: =_xlfn.XLOOKUP(C12,Validation!$B$2:$B$68,Validation!$A$2:$A$68) -> 12115 | F12: 36417 | G12: 1200 | H12: Hurricane (Typhoon) | K12: 0 | L12: 0 | M12: 0 | N12: 0 | O12: FL | P12: EST | R12: 2412730 | S12: Z | T12: 60 | U12: TBW | V12: 0 | W12: 0 | X12: OFFICIAL NWS OBS. | AG12: 36417 | AH12: 1800 | AN12: The outer rainbands of hurricane Floyd moved parallel to the east coast of Florida and produced tropical storm force wind gusts primarily across interior counties within West Central Florida. A maximum wind gust of 58 mph was reported at Lakeland Linder Airport around 1700 EST on the 14th._x000D_ _x000D_ Tropical storm force wind gusts uprooted a few large trees and downed power lines in and around Lakeland in Polk County. One mobile home lost its roof from tropical storm force winds on Rock Ridge Road in Lakeland. | AO12: 95
A13: 5717084 | B13: MANATEE (ZONE) | C13: =_xlfn.XLOOKUP(B13,Match!$A$2:$A$111,Match!$B$2:$B$111) -> Manatee, FL | D13: =_xlfn.XLOOKUP(C13,Validation!$B$2:$B$68,Validation!$A$2:$A$68) -> 12081 | F13: 36417 | G13: 1200 | H13: Hurricane (Typhoon) | K13: 0 | L13: 0 | M13: 0 | N13: 0 | O13: FL | P13: EST | R13: 2412730 | S13: Z | T13: 55 | U13: TBW | V13: 0 | W13: 0 | X13: OFFICIAL NWS OBS. | AG13: 36417 | AH13: 1800 | AN13: The outer rainbands of hurricane Floyd moved parallel to the east coast of Florida and produced tropical storm force wind gusts primarily across interior counties within West Central Florida. A maximum wind gust of 58 mph was reported at Lakeland Linder Airport around 1700 EST on the 14th._x000D_ _x000D_ Tropical storm force wind gusts uprooted a few large trees and downed power lines in and around Lakeland in Polk County. One mobile home lost its roof from tropical storm force winds on Rock Ridge Road in Lakeland. | AO13: 96
A14: 5717087 | B14: HARDEE (ZONE) | C14: =_xlfn.XLOOKUP(B14,Match!$A$2:$A$111,Match!$B$2:$B$111) -> Hardee, FL | D14: =_xlfn.XLOOKUP(C14,Validation!$B$2:$B$68,Validation!$A$2:$A$68) -> 12049 | F14: 36417 | G14: 1200 | H14: Hurricane (Typhoon) | K14: 0 | L14: 0 | M14: 0 | N14: 0 | O14: FL | P14: EST | R14: 2412730 | S14: Z | T14: 56 | U14: TBW | V14: 0 | W14: 0 | X14: OFFICIAL NWS OBS. | AG14: 36417 | AH14: 1800 | AN14: The outer rainbands of hurricane Floyd moved parallel to the east coast of Florida and produced tropical storm force wind gusts primarily across interior counties within West Central Florida. A maximum wind gust of 58 mph was reported at Lakeland Linder Airport around 1700 EST on the 14th._x000D_ _x000D_ Tropical storm force wind gusts uprooted a few large trees and downed power lines in and around Lakeland in Polk County. One mobile home lost its roof from tropical storm force winds on Rock Ridge Road in Lakeland. | AO14: 97
A15: 5717618 | B15: ST. LUCIE (ZONE) | C15: =_xlfn.XLOOKUP(B15,Match!$A$2:$A$111,Match!$B$2:$B$111) -> St. Lucie, FL | D15: =_xlfn.XLOOKUP(C15,Validation!$B$2:$B$68,Validation!$A$2:$A$68) -> 12111 | F15: 36417 | G15: 2000 | H15: Hurricane (Typhoon) | K15: 0 | L15: 0 | M15: 50000 | N15: 0 | O15: FL | P15: EST | R15: 2413683 | S15: Z | T15: 59 | U15: MLB | V15: 0 | W15: 0 | X15: EMERGENCY MANAGER | AG15: 36418 | AH15: 1200 | AN15: The center of Hurricane Floyd passed about 115 statute miles off the coast of east central Florida on September 15th. The areas hardest hit were coastal sections of Brevard and Volusia counties. Both counties experienced widespread wind gusts to near 70 mph. Initial damage estimates in Volusia County were near $42 Million. About ten million of that was due to beach erosion. Three hundred thirty plus homes were damaged by wind or falling trees. Thousands of people were left without power. A large section of the Main Street Pier was destroyed by heavy surf in Daytona Beach. In Brevard County damage estimates were near $10 million. About $8 million of that was due to beach erosion. A few beach front homes received major damage from surf and wind. Many highrise hotels received water damage from wind driven rain. Thousands of trees and power lines were blown down across the county._x000D_ _x000D_ Beach erosion and downed trees and power lines and damage to some homes were also reported across coastal sections of St. Lucie and Indian River counties. Inland, downed trees and power lines and minor wind damage to structures was also reported in Orange and Seminole counties. | AO15: 98
A16: 5717615 | B16: SEMINOLE (ZONE) | C16: =_xlfn.XLOOKUP(B16,Match!$A$2:$A$111,Match!$B$2:$B$111) -> Seminole, FL | D16: =_xlfn.XLOOKUP(C16,Validation!$B$2:$B$68,Validation!$A$2:$A$68) -> 12117 | F16: 36417 | G16: 2200 | H16: Hurricane (Typhoon) | K16: 0 | L16: 0 | M16: 400000 | N16: 0 | O16: FL | P16: EST | R16: 2413683 | S16: Z | T16: 46 | U16: MLB | V16: 0 | W16: 0 | X16: EMERGENCY MANAGER | AG16: 36418 | AH16: 1600 | AN16: The center of Hurricane Floyd passed about 115 statute miles off the coast of east central Florida on September 15th. The areas hardest hit were coastal sections of Brevard and Volusia counties. Both counties experienced widespread wind gusts to near 70 mph. Initial damage estimates in Volusia County were near $42 Million. About ten million of that was due to beach erosion. Three hundred thirty plus homes were damaged by wind or falling trees. Thousands of people were left without power. A large section of the Main Street Pier was destroyed by heavy surf in Daytona Beach. In Brevard County damage estimates were near $10 million. About $8 million of that was due to beach erosion. A few beach front homes received major damage from surf and wind. Many highrise hotels received water damage from wind driven rain. Thousands of trees and power lines were blown down across the county._x000D_ _x000D_ Beach erosion and downed trees and power lines and damage to some homes were also reported across coastal sections of St. Lucie and Indian River counties. Inland, downed trees and power lines and minor wind damage to structures was also reported in Orange and Seminole counties. | AO16: 99
A17: 5723962 | B17: BREVARD (ZONE) | C17: =_xlfn.XLOOKUP(B17,Match!$A$2:$A$111,Match!$B$2:$B$111) -> Brevard, FL | D17: =_xlfn.XLOOKUP(C17,Validation!$B$2:$B$68,Validation!$A$2:$A$68) -> 12009 | F17: 36417 | G17: 2200 | H17: Hurricane (Typhoon) | K17: 0 | L17: 0 | M17: 5000000 | N17: 0 | O17: FL | P17: EST | R17: 2413683 | S17: Z | T17: 47 | U17: MLB | V17: 0 | W17: 0 | X17: EMERGENCY MANAGER | AG17: 36418 | AH17: 1600 | AN17: The center of Hurricane Floyd passed about 115 statute miles off the coast of east central Florida on September 15th. The areas hardest hit were coastal sections of Brevard and Volusia counties. Both counties experienced widespread wind gusts to near 70 mph. Initial damage estimates in Volusia County were near $42 Million. About ten million of that was due to beach erosion. Three hundred thirty plus homes were damaged by wind or falling trees. Thousands of people were left without power. A large section of the Main Street Pier was destroyed by heavy surf in Daytona Beach. In Brevard County damage estimates were near $10 million. About $8 million of that was due to beach erosion. A few beach front homes received major damage from surf and wind. Many highrise hotels received water damage from wind driven rain. Thousands of trees and power lines were blown down across the county._x000D_ _x000D_ Beach erosion and downed trees and power lines and damage to some homes were also reported across coastal sections of St. Lucie and Indian River counties. Inland, downed trees and power lines and minor wind damage to structures was also reported in Orange and Seminole counties. | AO17: 100
... A27: 5716958 | B27: COASTAL PALM BEACH (ZONE) | C27: =_xlfn.XLOOKUP(B27,Match!$A$2:$A$111,Match!$B$2:$B$111) -> Palm Beach, FL | D27: =_xlfn.XLOOKUP(C27,Validation!$B$2:$B$68,Validation!$A$2:$A$68) -> 12099 | F27: 36447 | G27: 900 | H27: Hurricane (Typhoon) | K27: 0 | L27: 0 | M27: 68000000 | N27: 75000000 | O27: FL | P27: EST | R27: 2411770 | S27: Z | T27: 68 | U27: MFL | V27: 0 | W27: 0 | X27: NEWSPAPER | AG27: 36448 | AH27: 2300 | AN27: After lingering as a broad area of low pressure in the western Caribbean Sea for four days, a tropical depression formed just after midnight EDT on October 13 and became tropical storm Irene in the northwest Caribbean Sea later that morning. Irene moved north across western Cuba on October 14 and strengthened to hurricane intensity early on October 15 in the Straits of Florida. It then made its first landfall in south Florida in the lower Florida Keys around 9 AM EDT, October 15. After crossing Florida Bay the center of Irene made landfall on the peninsula near Cape Sable around 4 PM EDT, October 15 as a Category One intensity hurricane. It moved northeast across central Miami-Dade and Broward counties before exiting into the Atlantic just after midnight EDT on October 16 near Jupiter in northeast Palm Beach County._x000D_ _x000D_ Heavy rains and sustained winds of tropical storm force caused widespread flooding and power outages in the metropolitan areas of Miami-Dade, Broward and Palm Beach counties. The effects were similar, although somewhat more widespread, than those experienced in tropical storm Gordon in November 1994 and were reminiscent of the wet hurricanes in the 1930s and 1940s._x000D_ _x000D_ Rainfall totals in southeast Florida ranged from 6 to 17 inches with many areas getting 10 to 15 inches. The greatest reliable amount reported was 17.45 inches at Boynton Beach. The highest sustained wind over land was 60 mph at Miami Beach with many readings from 40 to 55 mph. Fowey Rocks Light reported sustained winds of 66 mph while the Miami NWS doppler radar estimated areas of sustained hurricane force winds in the Atlantic Ocean just off the southeast Florida coast. Among the highest recorded gusts were readings of 93 mph near Belle Glade, 85 mph at Homestead Air Reserve Base, 84 mph at Fowey Rocks Light, 74 mph at Turkey Point nuclear power plant and 70 mph at Miami International Airport. The lowest barometric pressure on the south Florida peninsula was 989.9 mb at Opa Locka Airport. Storm surge and beach erosion were minimal._x000D_ _x000D_ Four tornadoes touched down in Broward and Palm Beach counties, injuring 3 persons. Several other areas of localized wind damage were reported, especially near the southeast shore of Lake Okeechobee, and were likely attributable to convective downbursts._x000D_ _x000D_ There were no direct deaths from Irene, but eight persons died in the aftermath. Five persons were electrocuted by downed power lines, including three persons from one family. Three other persons drowned in vehicle-related accidents. Damage in southeast Florida, mainly from flooding is estimated near $600 million which includes $335 million in agricultural losses. An estimated 700,000 customers lost electricity. Flooding in a few residential areas lasted for a week displacing several hundred persons and isolating thousands more._x000D_ _x000D_ Other long-term ecological repercussions may be experienced from the flooding rains such as the effects of high water on Everglade's hammocks, and the effects of excessive fresh-water runoff on estuaries. | AO27: 110
A28: 5716844 | B28: MONROE/LOWER KEYS (ZONE) | C28: =_xlfn.XLOOKUP(B28,Match!$A$2:$A$111,Match!$B$2:$B$111) -> Monroe, FL | D28: =_xlfn.XLOOKUP(C28,Validation!$B$2:$B$68,Validation!$A$2:$A$68) -> 12087 | F28: 36447 | G28: 2100 | H28: Hurricane (Typhoon) | K28: 0 | L28: 0 | M28: 9300000 | N28: 0 | O28: FL | P28: EST | R28: 2413547 | S28: Z | T28: 78 | U28: EYW | V28: 0 | W28: 0 | X28: NWS STORM SURVEY | AG28: 36448 | AH28: 1800 | AO28: 111
A29: 5716845 | B29: MONROE/MIDDLE KEYS (ZONE) | C29: =_xlfn.XLOOKUP(B29,Match!$A$2:$A$111,Match!$B$2:$B$111) -> Monroe, FL | D29: =_xlfn.XLOOKUP(C29,Validation!$B$2:$B$68,Validation!$A$2:$A$68) -> 12087 | F29: 36447 | G29: 2200 | H29: Hurricane (Typhoon) | K29: 0 | L29: 0 | M29: 1500000 | N29: 0 | O29: FL | P29: EST | R29: 2413547 | S29: Z | T29: 77 | U29: EYW | V29: 0 | W29: 0 | X29: NWS STORM SURVEY | AG29: 36448 | AH29: 2000 | AO29: 112
A30: 5716846 | B30: MONROE/UPPER KEYS (ZONE) | C30: =_xlfn.XLOOKUP(B30,Match!$A$2:$A$111,Match!$B$2:$B$111) -> Monroe, FL | D30: =_xlfn.XLOOKUP(C30,Validation!$B$2:$B$68,Validation!$A$2:$A$68) -> 12087 | F30: 36447 | G30: 2300 | H30: Hurricane (Typhoon) | K30: 0 | L30: 0 | M30: 2670000 | N30: 0 | O30: FL | P30: EST | R30: 2413547 | S30: Z | T30: 76 | U30: EYW | V30: 0 | W30: 0 | X30: NWS STORM SURVEY | AG30: 36448 | AH30: 2100 | AO30: 113
A31: 5723286 | B31: DE SOTO (ZONE) | C31: =_xlfn.XLOOKUP(B31,Match!$A$2:$A$111,Match!$B$2:$B$111) -> DeSoto, FL | D31: =_xlfn.XLOOKUP(C31,Validation!$B$2:$B$68,Validation!$A$2:$A$68) -> 12027 | F31: 36448 | G31: 1200 | H31: Hurricane (Typhoon) | K31: 0 | L31: 0 | M31: 0 | N31: 0 | O31: FL | P31: EST | R31: 2413725 | S31: Z | T31: 61 | U31: TBW | V31: 0 | W31: 0 | X31: OFFICIAL NWS OBS. | AG31: 36449 | AH31: 1500 | AN31: The westernmost bands of Hurricane Irene produced occasional tropical storm force wind gusts across the interior counties of central Florida during the evening of October 15th and early morning of the 16th with no reported fatalities, injuries or damage._x000D_ _x000D_ Maximum wind gust observed was 42 mph from the northeast recorded at the automated surface observing site (ASOS) in Winter Haven of Polk County, Florida at 1533 EST on the 15th. Maximum 24 hour rainfall was .31 inches recorded at Page Field in Ft Myers of Lee County, Florida ending at 0800 EST on the 16th. Lowest sea-level pressure observed was 1000.0 mb at Regional Southwest Airport in Ft Myers of Lee County, Florida at 1917EST on the 15th. | AO31: 114
A32: 5723289 | B32: POLK (ZONE) | C32: =_xlfn.XLOOKUP(B32,Match!$A$2:$A$111,Match!$B$2:$B$111) -> Polk, FL | D32: =_xlfn.XLOOKUP(C32,Validation!$B$2:$B$68,Validation!$A$2:$A$68) -> 12105 | F32: 36448 | G32: 1200 | H32: Hurricane (Typhoon) | K32: 0 | L32: 0 | M32: 0 | N32: 0 | O32: FL | P32: EST | R32: 2413725 | S32: Z | T32: 52 | U32: TBW | V32: 0 | W32: 0 | X32: OFFICIAL NWS OBS. | AG32: 36449 | AH32: 1500 | AN32: The westernmost bands of Hurricane Irene produced occasional tropical storm force wind gusts across the interior counties of central Florida during the evening of October 15th and early morning of the 16th with no reported fatalities, injuries or damage._x000D_ _x000D_ Maximum wind gust observed was 42 mph from the northeast recorded at the automated surface observing site (ASOS) in Winter Haven of Polk County, Florida at 1533 EST on the 15th. Maximum 24 hour rainfall was .31 inches recorded at Page Field in Ft Myers of Lee County, Florida ending at 0800 EST on the 16th. Lowest sea-level pressure observed was 1000.0 mb at Regional Southwest Airport in Ft Myers of Lee County, Florida at 1917EST on the 15th. | AO32: 115
A33: 5723284 | B33: LEE (ZONE) | C33: =_xlfn.XLOOKUP(B33,Match!$A$2:$A$111,Match!$B$2:$B$111) -> Lee, FL | D33: =_xlfn.XLOOKUP(C33,Validation!$B$2:$B$68,Validation!$A$2:$A$68) -> 12071 | F33: 36448 | G33: 1200 | H33: Hurricane (Typhoon) | K33: 0 | L33: 0 | M33: 0 | N33: 0 | O33: FL | P33: EST | R33: 2413725 | S33: Z | T33: 65 | U33: TBW | V33: 0 | W33: 0 | X33: OFFICIAL NWS OBS. | AG33: 36449 | AH33: 1500 | AN33: The westernmost bands of Hurricane Irene produced occasional tropical storm force wind gusts across the interior counties of central Florida during the evening of October 15th and early morning of the 16th with no reported fatalities, injuries or damage._x000D_ _x000D_ Maximum wind gust observed was 42 mph from the northeast recorded at the automated surface observing site (ASOS) in Winter Haven of Polk County, Florida at 1533 EST on the 15th. Maximum 24 hour rainfall was .31 inches recorded at Page Field in Ft Myers of Lee County, Florida ending at 0800 EST on the 16th. Lowest sea-level pressure observed was 1000.0 mb at Regional Southwest Airport in Ft Myers of Lee County, Florida at 1917EST on the 15th. | AO33: 116
A34: 5723287 | B34: HARDEE (ZONE) | C34: =_xlfn.XLOOKUP(B34,Match!$A$2:$A$111,Match!$B$2:$B$111) -> Hardee, FL | D34: =_xlfn.XLOOKUP(C34,Validation!$B$2:$B$68,Validation!$A$2:$A$68) -> 12049 | F34: 36448 | G34: 1200 | H34: Hurricane (Typhoon) | K34: 0 | L34: 0 | M34: 0 | N34: 0 | O34: FL | P34: EST | R34: 2413725 | S34: Z | T34: 56 | U34: TBW | V34: 0 | W34: 0 | X34: OFFICIAL NWS OBS. | AG34: 36449 | AH34: 1500 | AN34: The westernmost bands of Hurricane Irene produced occasional tropical storm force wind gusts across the interior counties of central Florida during the evening of October 15th and early morning of the 16th with no reported fatalities, injuries or damage._x000D_ _x000D_ Maximum wind gust observed was 42 mph from the northeast recorded at the automated surface observing site (ASOS) in Winter Haven of Polk County, Florida at 1533 EST on the 15th. Maximum 24 hour rainfall was .31 inches recorded at Page Field in Ft Myers of Lee County, Florida ending at 0800 EST on the 16th. Lowest sea-level pressure observed was 1000.0 mb at Regional Southwest Airport in Ft Myers of Lee County, Florida at 1917EST on the 15th. | AO34: 117
A35: 5723285 | B35: CHARLOTTE (ZONE) | C35: =_xlfn.XLOOKUP(B35,Match!$A$2:$A$111,Match!$B$2:$B$111) -> Charlotte, FL | D35: =_xlfn.XLOOKUP(C35,Validation!$B$2:$B$68,Validation!$A$2:$A$68) -> 12015 | F35: 36448 | G35: 1200 | H35: Hurricane (Typhoon) | K35: 0 | L35: 0 | M35: 0 | N35: 0 | O35: FL | P35: EST | R35: 2413725 | S35: Z | T35: 62 | U35: TBW | V35: 0 | W35: 0 | X35: OFFICIAL NWS OBS. | AG35: 36449 | AH35: 1500 | AN35: The westernmost bands of Hurricane Irene produced occasional tropical storm force wind gusts across the interior counties of central Florida during the evening of October 15th and early morning of the 16th with no reported fatalities, injuries or damage._x000D_ _x000D_ Maximum wind gust observed was 42 mph from the northeast recorded at the automated surface observing site (ASOS) in Winter Haven of Polk County, Florida at 1533 EST on the 15th. Maximum 24 hour rainfall was .31 inches recorded at Page Field in Ft Myers of Lee County, Florida ending at 0800 EST on the 16th. Lowest sea-level pressure observed was 1000.0 mb at Regional Southwest Airport in Ft Myers of Lee County, Florida at 1917EST on the 15th. | AO35: 118
A36: 5723288 | B36: HIGHLANDS (ZONE) | C36: =_xlfn.XLOOKUP(B36,Match!$A$2:$A$111,Match!$B$2:$B$111) -> Highlands, FL | D36: =_xlfn.XLOOKUP(C36,Validation!$B$2:$B$68,Validation!$A$2:$A$68) -> 12055 | F36: 36448 | G36: 1200 | H36: Hurricane (Typhoon) | K36: 0 | L36: 0 | M36: 0 | N36: 0 | O36: FL | P36: EST | R36: 2413725 | S36: Z | T36: 57 | U36: TBW | V36: 0 | W36: 0 | X36: OFFICIAL NWS OBS. | AG36: 36449 | AH36: 1500 | AN36: The westernmost bands of Hurricane Irene produced occasional tropical storm force wind gusts across the interior counties of central Florida during the evening of October 15th and early morning of the 16th with no reported fatalities, injuries or damage._x000D_ _x000D_ Maximum wind gust observed was 42 mph from the northeast recorded at the automated surface observing site (ASOS) in Winter Haven of Polk County, Florida at 1533 EST on the 15th. Maximum 24 hour rainfall was .31 inches recorded at Page Field in Ft Myers of Lee County, Florida ending at 0800 EST on the 16th. Lowest sea-level pressure observed was 1000.0 mb at Regional Southwest Airport in Ft Myers of Lee County, Florida at 1917EST on the 15th. | AO36: 119
A37: 5717621 | B37: INDIAN RIVER (ZONE) | C37: =_xlfn.XLOOKUP(B37,Match!$A$2:$A$111,Match!$B$2:$B$111) -> Indian River, FL | D37: =_xlfn.XLOOKUP(C37,Validation!$B$2:$B$68,Validation!$A$2:$A$68) -> 12061 | F37: 36448 | G37: 2000 | H37: Hurricane (Typhoon) | K37: 0 | L37: 0 | M37: 10000000 | N37: 0 | O37: FL | P37: EST | R37: 2413684 | S37: Z | T37: 54 | U37: MLB | V37: 0 | W37: 0 | X37: EMERGENCY MANAGER | AG37: 36449 | AH37: 1200 | AN37: Minimal Hurricane Irene moved northeast from the Florida Keys across south Florida and emerged over the Atlantic near Ft. Pierce. Even though the storm was classified a category one hurricane, no sustained hurricane force winds were observed in east central Florida. Winds gusted from 60 to 70 mph over coastal locations from Ft. Pierce to Daytona Beach. _x000D_ _x000D_ In Martin and St. Lucie counties the greatest impact from the storm was flooding. From 5 to 9 inches of rain fell over the area flooding 300 homes. About 50 homes had major wind damage and thousands of trees were blown down. _x000D_ _x000D_ In Volusia, Brevard and Indian River counties hundreds of homes received minor wind damage and about 50 residences were seriously damaged. The hardest hit areas were beach front communities. Many houses and high rise hotels suffered roof damage and damage from wind driven rain. A barge broke free during high winds and damaged the causeway bridge on US Highway 528 near Cape Canaveral. Substantial beach erosion was reported along the entire coast. From 4 to 10 feet of beach front was lost in most areas with damage estimated in the millions of dollars in each county. | AO37: 120
A38: 5717622 | B38: BREVARD (ZONE) | C38: =_xlfn.XLOOKUP(B38,Match!$A$2:$A$111,Match!$B$2:$B$111) -> Brevard, FL | D38: =_xlfn.XLOOKUP(C38,Validation!$B$2:$B$68,Validation!$A$2:$A$68) -> 12009 | F38: 36448 | G38: 2000 | H38: Hurricane (Typhoon) | K38: 0 | L38: 0 | M38: 12000000 | N38: 0 | O38: FL | P38: EST | R38: 2413684 | S38: Z | T38: 47 | U38: MLB | V38: 0 | W38: 0 | X38: EMERGENCY MANAGER | AG38: 36449 | AH38: 1200 | AN38: Minimal Hurricane Irene moved northeast from the Florida Keys across south Florida and emerged over the Atlantic near Ft. Pierce. Even though the storm was classified a category one hurricane, no sustained hurricane force winds were observed in east central Florida. Winds gusted from 60 to 70 mph over coastal locations from Ft. Pierce to Daytona Beach. _x000D_ _x000D_ In Martin and St. Lucie counties the greatest impact from the storm was flooding. From 5 to 9 inches of rain fell over the area flooding 300 homes. About 50 homes had major wind damage and thousands of trees were blown down. _x000D_ _x000D_ In Volusia, Brevard and Indian River counties hundreds of homes received minor wind damage and about 50 residences were seriously damaged. The hardest hit areas were beach front communities. Many houses and high rise hotels suffered roof damage and damage from wind driven rain. A barge broke free during high winds and damaged the causeway bridge on US Highway 528 near Cape Canaveral. Substantial beach erosion was reported along the entire coast. From 4 to 10 feet of beach front was lost in most areas with damage estimated in the millions of dollars in each county. | AO38: 121
A39: 5717620 | B39: ST. LUCIE (ZONE) | C39: =_xlfn.XLOOKUP(B39,Match!$A$2:$A$111,Match!$B$2:$B$111) -> St. Lucie, FL | D39: =_xlfn.XLOOKUP(C39,Validation!$B$2:$B$68,Validation!$A$2:$A$68) -> 12111 | F39: 36448 | G39: 2000 | H39: Hurricane (Typhoon) | K39: 0 | L39: 0 | M39: 6000000 | N39: 0 | O39: FL | P39: EST | R39: 2413684 | S39: Z | T39: 59 | U39: MLB | V39: 0 | W39: 0 | X39: EMERGENCY MANAGER | AG39: 36449 | AH39: 1200 | AN39: Minimal Hurricane Irene moved northeast from the Florida Keys across south Florida and emerged over the Atlantic near Ft. Pierce. Even though the storm was classified a category one hurricane, no sustained hurricane force winds were observed in east central Florida. Winds gusted from 60 to 70 mph over coastal locations from Ft. Pierce to Daytona Beach. _x000D_ _x000D_ In Martin and St. Lucie counties the greatest impact from the storm was flooding. From 5 to 9 inches of rain fell over the area flooding 300 homes. About 50 homes had major wind damage and thousands of trees were blown down. _x000D_ _x000D_ In Volusia, Brevard and Indian River counties hundreds of homes received minor wind damage and about 50 residences were seriously damaged. The hardest hit areas were beach front communities. Many houses and high rise hotels suffered roof damage and damage from wind driven rain. A barge broke free during high winds and damaged the causeway bridge on US Highway 528 near Cape Canaveral. Substantial beach erosion was reported along the entire coast. From 4 to 10 feet of beach front was lost in most areas with damage estimated in the millions of dollars in each county. | AO39: 122
A40: 5717619 | B40: MARTIN (ZONE) | C40: =_xlfn.XLOOKUP(B40,Match!$A$2:$A$111,Match!$B$2:$B$111) -> Martin, FL | D40: =_xlfn.XLOOKUP(C40,Validation!$B$2:$B$68,Validation!$A$2:$A$68) -> 12085 | F40: 36448 | G40: 2000 | H40: Hurricane (Typhoon) | K40: 0 | L40: 0 | M40: 8000000 | N40: 0 | O40: FL | P40: EST | R40: 2413684 | S40: Z | T40: 64 | U40: MLB | V40: 0 | W40: 0 | X40: EMERGENCY MANAGER | AG40: 36449 | AH40: 1200 | AN40: Minimal Hurricane Irene moved northeast from the Florida Keys across south Florida and emerged over the Atlantic near Ft. Pierce. Even though the storm was classified a category one hurricane, no sustained hurricane force winds were observed in east central Florida. Winds gusted from 60 to 70 mph over coastal locations from Ft. Pierce to Daytona Beach. _x000D_ _x000D_ In Martin and St. Lucie counties the greatest impact from the storm was flooding. From 5 to 9 inches of rain fell over the area flooding 300 homes. About 50 homes had major wind damage and thousands of trees were blown down. _x000D_ _x000D_ In Volusia, Brevard and Indian River counties hundreds of homes received minor wind damage and about 50 residences were seriously damaged. The hardest hit areas were beach front communities. Many houses and high rise hotels suffered roof damage and damage from wind driven rain. A barge broke free during high winds and damaged the causeway bridge on US Highway 528 near Cape Canaveral. Substantial beach erosion was reported along the entire coast. From 4 to 10 feet of beach front was lost in most areas with damage estimated in the millions of dollars in each county. | AO40: 123
A41: 5717623 | B41: VOLUSIA (ZONE) | C41: =_xlfn.XLOOKUP(B41,Match!$A$2:$A$111,Match!$B$2:$B$111) -> Volusia, FL | D41: =_xlfn.XLOOKUP(C41,Validation!$B$2:$B$68,Validation!$A$2:$A$68) -> 12127 | F41: 36448 | G41: 2000 | H41: Hurricane (Typhoon) | K41: 0 | L41: 0 | M41: 15000000 | N41: 0 | O41: FL | P41: EST | R41: 2413684 | S41: Z | T41: 41 | U41: MLB | V41: 0 | W41: 0 | X41: EMERGENCY MANAGER | AG41: 36449 | AH41: 1700 | AN41: Minimal Hurricane Irene moved northeast from the Florida Keys across south Florida and emerged over the Atlantic near Ft. Pierce. Even though the storm was classified a category one hurricane, no sustained hurricane force winds were observed in east central Florida. Winds gusted from 60 to 70 mph over coastal locations from Ft. Pierce to Daytona Beach. _x000D_ _x000D_ In Martin and St. Lucie counties the greatest impact from the storm was flooding. From 5 to 9 inches of rain fell over the area flooding 300 homes. About 50 homes had major wind damage and thousands of trees were blown down. _x000D_ _x000D_ In Volusia, Brevard and Indian River counties hundreds of homes received minor wind damage and about 50 residences were seriously damaged. The hardest hit areas were beach front communities. Many houses and high rise hotels suffered roof damage and damage from wind driven rain. A barge broke free during high winds and damaged the causeway bridge on US Highway 528 near Cape Canaveral. Substantial beach erosion was reported along the entire coast. From 4 to 10 feet of beach front was lost in most areas with damage estimated in the millions of dollars in each county. | AO41: 124
A42: 5722400 | B42: FLAGLER (ZONE) | C42: =_xlfn.XLOOKUP(B42,Match!$A$2:$A$111,Match!$B$2:$B$111) -> Flagler, FL | D42: =_xlfn.XLOOKUP(C42,Validation!$B$2:$B$68,Validation!$A$2:$A$68) -> 12035 | F42: 36449 | G42: 1500 | H42: Hurricane (Typhoon) | K42: 0 | L42: 0 | M42: 600000 | N42: 0 | O42: FL | P42: EST | R42: 2414411 | S42: Z | T42: 38 | U42: JAX | V42: 0 | W42: 0 | X42: EMERGENCY MANAGER | AG42: 36450 | AH42: 400 | AN42: Hurricane Irene - Three single family homes and one multi-family structure received major damage. 167 single family homes, 6 multi-family and 18 mobile and 18 businesses with minor damage. Numerous reports of trees and power lines blown down. Minor flooding occurred in the northern portion of the county near Marineland. Minor beach erosion. A 74 mph wind gust was reported between 16/2000 and 16/2030 UTC by the Flagler Vol. Fire Department. | AO42: 125
A43: 5722401 | B43: ST. JOHNS (ZONE) | C43: =_xlfn.XLOOKUP(B43,Match!$A$2:$A$111,Match!$B$2:$B$111) -> St. Johns, FL | D43: =_xlfn.XLOOKUP(C43,Validation!$B$2:$B$68,Validation!$A$2:$A$68) -> 12109 | F43: 36449 | G43: 1700 | H43: Hurricane (Typhoon) | K43: 0 | L43: 0 | M43: 300000 | N43: 0 | O43: FL | P43: EST | R43: 2413088 | S43: Z | T43: 33 | U43: JAX | V43: 0 | W43: 0 | X43: EMERGENCY MANAGER | AG43: 36450 | AH43: 1800 | AM43: Hurricane Irene - Minor beach erosion and flooding. Numerous reports of tree and power lines blown down. Max wind gust - 77 mph, St. Augustine (SAUF1) at 170200 UTC. | AO43: 126
A44: 5722402 | B44: DUVAL (ZONE) | C44: =_xlfn.XLOOKUP(B44,Match!$A$2:$A$111,Match!$B$2:$B$111) -> Duval, FL | D44: =_xlfn.XLOOKUP(C44,Validation!$B$2:$B$68,Validation!$A$2:$A$68) -> 12031 | F44: 36449 | G44: 1800 | H44: Hurricane (Typhoon) | K44: 0 | L44: 0 | M44: 300000 | N44: 0 | O44: FL | P44: EST | R44: 2414412 | S44: Z | T44: 25 | U44: JAX | V44: 0 | W44: 0 | X44: EMERGENCY MANAGER | AG44: 36450 | AH44: 600 | AM44: Hurricane Irene - Numerous reports of trees and power lines blown down. Max wind gust - 55 mph, Mayport Navy Base at 170200 UTC. Minor beach erosion. | AO44: 127
A45: 5157574 | B45: LEE (ZONE) | C45: =_xlfn.XLOOKUP(B45,Match!$A$2:$A$111,Match!$B$2:$B$111) -> Lee, FL | D45: =_xlfn.XLOOKUP(C45,Validation!$B$2:$B$68,Validation!$A$2:$A$68) -> 12071 | F45: 36786 | G45: 330 | H45: Hurricane (Typhoon) | K45: 0 | L45: 0 | M45: 500000 | N45: 0 | O45: FL | P45: EST | R45: 1104015 | S45: Z | T45: 65 | U45: TBW | V45: 0 | W45: 0 | X45: AWOS | Y45: ASOS | Z45: MESONET | AA45: ETC | AJ45: 36786 | AK45: 1600 | AQ45: Hurricane Gordon moved northeast across the eastern Gulf of Mexico and brought mainly 30 to 40 mph sustained winds and 50 to nearly 70 mph tropical storm force wind gusts to mainly coastal areas of Southwest and West Central Florida throughout the daylight hours of the 17th. Gordon's ill-defined center made landfall near the Suwannee River around midnight of the 18th. Official, maximum sustained winds of 53 mph, with gusts as high as 68 mph, were observed at the C-MAN automated weather sensor at Cedar Key in Levy county prior to landfall near the mouth of the Suwannee River during the late evening of the 17th._x000D_ _x000D_ Hurricane Gordon produced maximum storm tides above mean sea level of 2 to 4 feet from Lee north to Manatee county, 4 to 5.5 feet along the Pinellas and Hillsborough county coastlines, and 2 to 4 feet from Pasco north to Levy county on the 17th._x000D_ _x000D_ Coastal flooding from storm surge was minimal from Lee county north to the Tampa metropolitan area. Near downtown Tampa, a foot of water covered the south and northern lanes of Bayshore Boulevard during midday on the 17th. Coastal flood waters between one and two feet covered coastal roads along Longboat Key in Manatee county and Siesta and Casey Keys in Sarasota county. In Pinellas county, nearly a foot of water covered coastal roads from St. Pete Beach to Clearwater. The Courtney Campbell Parkway, seperating Pinellas and Hillsborough counties, was closed, due to storm surge flooding, from nearly 5 to 9 pm on the 17th._x000D_ _x000D_ Beach erosion was minor from Lee north to Charlotte, moderate to severe along Sarasota and Manatee counties, minor to moderate over Manatee, Pinellas, Pasco and Hernando counties. At Bradenton Beach in Manatee county, nearly 100 feet of pristine beach, five to six feet in depth, was stripped away by wave action from Hurricane Gordon. In Sarasota county, storm surge and wave action from Gordon caused nearly 1.1 million dollars in beach erosion while in Manatee county, beach erosion was estimated at 500 thousand dollars._x000D_ _x000D_ Inland flooding from rainfall occurred over low-lying and urban areas in mainly Lee, Charlotte, Sarasota, Manatee, Hardee, DeSoto, Highlands and southern Polk counties (see flood entries)._x000D_ _x000D_ Eastern rain bands of Hurricane Gordon spawned at least five known tornadoes, two F1's and three F0's over Central and Southwest Florida (see tornado entries)._x000D_ _x000D_ Damage in Levy county was confined to roofs and toppled trees, mainly in the Cedar Key area, where a total of $100,000 dollars was estimated._x000D_ _x000D_ Damage in Citrus county was confined to a few downed trees, power lines and snapped branches from Sulphur Springs south to Ozello mounting to less than $25,000 dollars._x000D_ _x000D_ Damage in Hernando county was confined to ten homes that suffered floodwater damage along the coast along with a few toppled trees and downed power lines. Damage in Hernando county was estimated at $100,000 dollars._x000D_ _x000D_ Damage in Pasco county was confined to 15 roof damaged villas, downed trees and damaged vehicles in the New Port Colony Villas subdivsion in New Port Richey estimated at $250,000 dollars._x000D_ _x000D_ In Pinellas county, 51 single-family homes, 32 mobile homes, 27 multi-family homes and 24 businesses sustained minor wind or water damage. Estimated cost of the damage in Pinellas county was nearly $500,000 dollars._x000D_ _x000D_ In Hillsborough county, 40 homes in low lying coastal areas from Ruskin to Gibsonton to Riverview, incurred flooding from storm surge. Also, several homes were damaged from wind toppled trees and large branches throughout Hillsborough county. Estimated cost of the damage in Hillsborough county was near $500,000 dollars._x000D_ _x000D_ In Manatee county, 25 homes and businesses were flooded in Bradenton Beach and several homes incurred minor to moderate roof damage in Anna Maria. At Coquina Beach in Manatee county, 60 mph wind gusts, associated with an outer feeder band of Gordon, toppled life guard towers and destroyed an anemometer. Property damage from Hurricane Gordon was estimated at nearly $500,000 dollars in Manatee county._x000D_ _x000D_ In Sarasota county, eight foot high waves, caused nearly $600,000 in property damage to the Venice Municipal Fishing Pier. The hurricane induced waves ripped a 20 foot section and three 50 foot concrete pilings from the northern section of the pier._x000D_ _x000D_ In Lee county, tropical storm force winds caused roof, awning and lanai damage to nine homes, toppled several large trees and branches, and downed power lines across Cape Coral and Ft. Myers. Also, tornadoes, associated with outer feeder bands of Hurricane Gordon, caused significant damage on Sanibel Island of extreme western Lee county (see Lee county tornado entries)._x000D_ _x000D_ Max Wind Gust: 68 mph - Cedar Key, Levy Co. 2153 EST 09/17_x000D_ Lowest Pressure: 994.2 mb - Cedar Key, Levy Co. 2200 EST 09/17_x000D_ Max Rainfall: 6.39 in - Page Field, Ft. Myers, Lee Co. 0000-2400 EST 09/17 | AR45: 128
A46: 5157575 | B46: CHARLOTTE (ZONE) | C46: =_xlfn.XLOOKUP(B46,Match!$A$2:$A$111,Match!$B$2:$B$111) -> Charlotte, FL | D46: =_xlfn.XLOOKUP(C46,Validation!$B$2:$B$68,Validation!$A$2:$A$68) -> 12015 | F46: 36786 | G46: 400 | H46: Hurricane (Typhoon) | K46: 0 | L46: 0 | M46: 150000 | N46: 0 | O46: FL | P46: EST | R46: 1104015 | S46: Z | T46: 62 | U46: TBW | V46: 0 | W46: 0 | X46: AWOS | Y46: ASOS | Z46: MESONET | AA46: ETC | AJ46: 36786 | AK46: 1600 | AQ46: Hurricane Gordon moved northeast across the eastern Gulf of Mexico and brought mainly 30 to 40 mph sustained winds and 50 to nearly 70 mph tropical storm force wind gusts to mainly coastal areas of Southwest and West Central Florida throughout the daylight hours of the 17th. Gordon's ill-defined center made landfall near the Suwannee River around midnight of the 18th. Official, maximum sustained winds of 53 mph, with gusts as high as 68 mph, were observed at the C-MAN automated weather sensor at Cedar Key in Levy county prior to landfall near the mouth of the Suwannee River during the late evening of the 17th._x000D_ _x000D_ Hurricane Gordon produced maximum storm tides above mean sea level of 2 to 4 feet from Lee north to Manatee county, 4 to 5.5 feet along the Pinellas and Hillsborough county coastlines, and 2 to 4 feet from Pasco north to Levy county on the 17th._x000D_ _x000D_ Coastal flooding from storm surge was minimal from Lee county north to the Tampa metropolitan area. Near downtown Tampa, a foot of water covered the south and northern lanes of Bayshore Boulevard during midday on the 17th. Coastal flood waters between one and two feet covered coastal roads along Longboat Key in Manatee county and Siesta and Casey Keys in Sarasota county. In Pinellas county, nearly a foot of water covered coastal roads from St. Pete Beach to Clearwater. The Courtney Campbell Parkway, seperating Pinellas and Hillsborough counties, was closed, due to storm surge flooding, from nearly 5 to 9 pm on the 17th._x000D_ _x000D_ Beach erosion was minor from Lee north to Charlotte, moderate to severe along Sarasota and Manatee counties, minor to moderate over Manatee, Pinellas, Pasco and Hernando counties. At Bradenton Beach in Manatee county, nearly 100 feet of pristine beach, five to six feet in depth, was stripped away by wave action from Hurricane Gordon. In Sarasota county, storm surge and wave action from Gordon caused nearly 1.1 million dollars in beach erosion while in Manatee county, beach erosion was estimated at 500 thousand dollars._x000D_ _x000D_ Inland flooding from rainfall occurred over low-lying and urban areas in mainly Lee, Charlotte, Sarasota, Manatee, Hardee, DeSoto, Highlands and southern Polk counties (see flood entries)._x000D_ _x000D_ Eastern rain bands of Hurricane Gordon spawned at least five known tornadoes, two F1's and three F0's over Central and Southwest Florida (see tornado entries)._x000D_ _x000D_ Damage in Levy county was confined to roofs and toppled trees, mainly in the Cedar Key area, where a total of $100,000 dollars was estimated._x000D_ _x000D_ Damage in Citrus county was confined to a few downed trees, power lines and snapped branches from Sulphur Springs south to Ozello mounting to less than $25,000 dollars._x000D_ _x000D_ Damage in Hernando county was confined to ten homes that suffered floodwater damage along the coast along with a few toppled trees and downed power lines. Damage in Hernando county was estimated at $100,000 dollars._x000D_ _x000D_ Damage in Pasco county was confined to 15 roof damaged villas, downed trees and damaged vehicles in the New Port Colony Villas subdivsion in New Port Richey estimated at $250,000 dollars._x000D_ _x000D_ In Pinellas county, 51 single-family homes, 32 mobile homes, 27 multi-family homes and 24 businesses sustained minor wind or water damage. Estimated cost of the damage in Pinellas county was nearly $500,000 dollars._x000D_ _x000D_ In Hillsborough county, 40 homes in low lying coastal areas from Ruskin to Gibsonton to Riverview, incurred flooding from storm surge. Also, several homes were damaged from wind toppled trees and large branches throughout Hillsborough county. Estimated cost of the damage in Hillsborough county was near $500,000 dollars._x000D_ _x000D_ In Manatee county, 25 homes and businesses were flooded in Bradenton Beach and several homes incurred minor to moderate roof damage in Anna Maria. At Coquina Beach in Manatee county, 60 mph wind gusts, associated with an outer feeder band of Gordon, toppled life guard towers and destroyed an anemometer. Property damage from Hurricane Gordon was estimated at nearly $500,000 dollars in Manatee county._x000D_ _x000D_ In Sarasota county, eight foot high waves, caused nearly $600,000 in property damage to the Venice Municipal Fishing Pier. The hurricane induced waves ripped a 20 foot section and three 50 foot concrete pilings from the northern section of the pier._x000D_ _x000D_ In Lee county, tropical storm force winds caused roof, awning and lanai damage to nine homes, toppled several large trees and branches, and downed power lines across Cape Coral and Ft. Myers. Also, tornadoes, associated with outer feeder bands of Hurricane Gordon, caused significant damage on Sanibel Island of extreme western Lee county (see Lee county tornado entries)._x000D_ _x000D_ Max Wind Gust: 68 mph - Cedar Key, Levy Co. 2153 EST 09/17_x000D_ Lowest Pressure: 994.2 mb - Cedar Key, Levy Co. 2200 EST 09/17_x000D_ Max Rainfall: 6.39 in - Page Field, Ft. Myers, Lee Co. 0000-2400 EST 09/17 | AR46: 129
A47: 5157588 | B47: PINELLAS (ZONE) | C47: =_xlfn.XLOOKUP(B47,Match!$A$2:$A$111,Match!$B$2:$B$111) -> Pinellas, FL | D47: =_xlfn.XLOOKUP(C47,Validation!$B$2:$B$68,Validation!$A$2:$A$68) -> 12103 | F47: 36786 | G47: 500 | H47: Hurricane (Typhoon) | K47: 0 | L47: 0 | M47: 10000 | N47: 0 | O47: FL | P47: EST | R47: 1104015 | S47: Z | T47: 50 | U47: TBW | V47: 0 | W47: 0 | X47: AWOS | Y47: ASOS | Z47: MESONET | AA47: ETC | AJ47: 36787 | AK47: 400 | AQ47: Hurricane Gordon moved northeast across the eastern Gulf of Mexico and brought mainly 30 to 40 mph sustained winds and 50 to nearly 70 mph tropical storm force wind gusts to mainly coastal areas of Southwest and West Central Florida throughout the daylight hours of the 17th. Gordon's ill-defined center made landfall near the Suwannee River around midnight of the 18th. Official, maximum sustained winds of 53 mph, with gusts as high as 68 mph, were observed at the C-MAN automated weather sensor at Cedar Key in Levy county prior to landfall near the mouth of the Suwannee River during the late evening of the 17th._x000D_ _x000D_ Hurricane Gordon produced maximum storm tides above mean sea level of 2 to 4 feet from Lee north to Manatee county, 4 to 5.5 feet along the Pinellas and Hillsborough county coastlines, and 2 to 4 feet from Pasco north to Levy county on the 17th._x000D_ _x000D_ Coastal flooding from storm surge was minimal from Lee county north to the Tampa metropolitan area. Near downtown Tampa, a foot of water covered the south and northern lanes of Bayshore Boulevard during midday on the 17th. Coastal flood waters between one and two feet covered coastal roads along Longboat Key in Manatee county and Siesta and Casey Keys in Sarasota county. In Pinellas county, nearly a foot of water covered coastal roads from St. Pete Beach to Clearwater. The Courtney Campbell Parkway, seperating Pinellas and Hillsborough counties, was closed, due to storm surge flooding, from nearly 5 to 9 pm on the 17th._x000D_ _x000D_ Beach erosion was minor from Lee north to Charlotte, moderate to severe along Sarasota and Manatee counties, minor to moderate over Manatee, Pinellas, Pasco and Hernando counties. At Bradenton Beach in Manatee county, nearly 100 feet of pristine beach, five to six feet in depth, was stripped away by wave action from Hurricane Gordon. In Sarasota county, storm surge and wave action from Gordon caused nearly 1.1 million dollars in beach erosion while in Manatee county, beach erosion was estimated at 500 thousand dollars._x000D_ _x000D_ Inland flooding from rainfall occurred over low-lying and urban areas in mainly Lee, Charlotte, Sarasota, Manatee, Hardee, DeSoto, Highlands and southern Polk counties (see flood entries)._x000D_ _x000D_ Eastern rain bands of Hurricane Gordon spawned at least five known tornadoes, two F1's and three F0's over Central and Southwest Florida (see tornado entries)._x000D_ _x000D_ Damage in Levy county was confined to roofs and toppled trees, mainly in the Cedar Key area, where a total of $100,000 dollars was estimated._x000D_ _x000D_ Damage in Citrus county was confined to a few downed trees, power lines and snapped branches from Sulphur Springs south to Ozello mounting to less than $25,000 dollars._x000D_ _x000D_ Damage in Hernando county was confined to ten homes that suffered floodwater damage along the coast along with a few toppled trees and downed power lines. Damage in Hernando county was estimated at $100,000 dollars._x000D_ _x000D_ Damage in Pasco county was confined to 15 roof damaged villas, downed trees and damaged vehicles in the New Port Colony Villas subdivsion in New Port Richey estimated at $250,000 dollars._x000D_ _x000D_ In Pinellas county, 51 single-family homes, 32 mobile homes, 27 multi-family homes and 24 businesses sustained minor wind or water damage. Estimated cost of the damage in Pinellas county was nearly $500,000 dollars._x000D_ _x000D_ In Hillsborough county, 40 homes in low lying coastal areas from Ruskin to Gibsonton to Riverview, incurred flooding from storm surge. Also, several homes were damaged from wind toppled trees and large branches throughout Hillsborough county. Estimated cost of the damage in Hillsborough county was near $500,000 dollars._x000D_ _x000D_ In Manatee county, 25 homes and businesses were flooded in Bradenton Beach and several homes incurred minor to moderate roof damage in Anna Maria. At Coquina Beach in Manatee county, 60 mph wind gusts, associated with an outer feeder band of Gordon, toppled life guard towers and destroyed an anemometer. Property damage from Hurricane Gordon was estimated at nearly $500,000 dollars in Manatee county._x000D_ _x000D_ In Sarasota county, eight foot high waves, caused nearly $600,000 in property damage to the Venice Municipal Fishing Pier. The hurricane induced waves ripped a 20 foot section and three 50 foot concrete pilings from the northern section of the pier._x000D_ _x000D_ In Lee county, tropical storm force winds caused roof, awning and lanai damage to nine homes, toppled several large trees and branches, and downed power lines across Cape Coral and Ft. Myers. Also, tornadoes, associated with outer feeder bands of Hurricane Gordon, caused significant damage on Sanibel Island of extreme western Lee county (see Lee county tornado entries)._x000D_ _x000D_ Max Wind Gust: 68 mph - Cedar Key, Levy Co. 2153 EST 09/17_x000D_ Lowest Pressure: 994.2 mb - Cedar Key, Levy Co. 2200 EST 09/17_x000D_ Max Rainfall: 6.39 in - Page Field, Ft. Myers, Lee Co. 0000-2400 EST 09/17 | AR47: 130
